Workbook

Sheet Summary
A1: Master-in-Equity sales — summary
A2: All figures are formulas over the "All cases" sheet; re-run the crawler and paste new rows there.
A4: County | B4: Cases | C4: Scheduled | D4: Cancelled / withdrawn | E4: Deficiency demanded | F4: Deficiency waived | G4: With judgment $ | H4: Total judgment $ (scheduled) | I4: With FMV
A5: Charleston | B5: =COUNTIF('All cases'!$A:$A,A5) | C5: =COUNTIFS('All cases'!$A:$A,A5,'All cases'!$E:$E,"scheduled") | D5: =B5-C5 | E5: =COUNTIFS('All cases'!$A:$A,A5,'All cases'!$J:$J,"demanded") | F5: =COUNTIFS('All cases'!$A:$A,A5,'All cases'!$J:$J,"waived") | G5: =COUNTIFS('All cases'!$A:$A,A5,'All cases'!$K:$K,">0") | H5: =SUMIFS('All cases'!$K:$K,'All cases'!$A:$A,A5,'All cases'!$E:$E,"scheduled") | I5: =COUNTIFS('All cases'!$A:$A,A5,'All cases'!$Q:$Q,">0")
A6: Georgetown | B6: =COUNTIF('All cases'!$A:$A,A6) | C6: =COUNTIFS('All cases'!$A:$A,A6,'All cases'!$E:$E,"scheduled") | D6: =B6-C6 | E6: =COUNTIFS('All cases'!$A:$A,A6,'All cases'!$J:$J,"demanded") | F6: =COUNTIFS('All cases'!$A:$A,A6,'All cases'!$J:$J,"waived") | G6: =COUNTIFS('All cases'!$A:$A,A6,'All cases'!$K:$K,">0") | H6: =SUMIFS('All cases'!$K:$K,'All cases'!$A:$A,A6,'All cases'!$E:$E,"scheduled") | I6: =COUNTIFS('All cases'!$A:$A,A6,'All cases'!$Q:$Q,">0")
A7: Greenville | B7: =COUNTIF('All cases'!$A:$A,A7) | C7: =COUNTIFS('All cases'!$A:$A,A7,'All cases'!$E:$E,"scheduled") | D7: =B7-C7 | E7: =COUNTIFS('All cases'!$A:$A,A7,'All cases'!$J:$J,"demanded") | F7: =COUNTIFS('All cases'!$A:$A,A7,'All cases'!$J:$J,"waived") | G7: =COUNTIFS('All cases'!$A:$A,A7,'All cases'!$K:$K,">0") | H7: =SUMIFS('All cases'!$K:$K,'All cases'!$A:$A,A7,'All cases'!$E:$E,"scheduled") | I7: =COUNTIFS('All cases'!$A:$A,A7,'All cases'!$Q:$Q,">0")
A8: Horry | B8: =COUNTIF('All cases'!$A:$A,A8) | C8: =COUNTIFS('All cases'!$A:$A,A8,'All cases'!$E:$E,"scheduled") | D8: =B8-C8 | E8: =COUNTIFS('All cases'!$A:$A,A8,'All cases'!$J:$J,"demanded") | F8: =COUNTIFS('All cases'!$A:$A,A8,'All cases'!$J:$J,"waived") | G8: =COUNTIFS('All cases'!$A:$A,A8,'All cases'!$K:$K,">0") | H8: =SUMIFS('All cases'!$K:$K,'All cases'!$A:$A,A8,'All cases'!$E:$E,"scheduled") | I8: =COUNTIFS('All cases'!$A:$A,A8,'All cases'!$Q:$Q,">0")
A9: Pickens | B9: =COUNTIF('All cases'!$A:$A,A9) | C9: =COUNTIFS('All cases'!$A:$A,A9,'All cases'!$E:$E,"scheduled") | D9: =B9-C9 | E9: =COUNTIFS('All cases'!$A:$A,A9,'All cases'!$J:$J,"demanded") | F9: =COUNTIFS('All cases'!$A:$A,A9,'All cases'!$J:$J,"waived") | G9: =COUNTIFS('All cases'!$A:$A,A9,'All cases'!$K:$K,">0") | H9: =SUMIFS('All cases'!$K:$K,'All cases'!$A:$A,A9,'All cases'!$E:$E,"scheduled") | I9: =COUNTIFS('All cases'!$A:$A,A9,'All cases'!$Q:$Q,">0")
A10: Spartanburg | B10: =COUNTIF('All cases'!$A:$A,A10) | C10: =COUNTIFS('All cases'!$A:$A,A10,'All cases'!$E:$E,"scheduled") | D10: =B10-C10 | E10: =COUNTIFS('All cases'!$A:$A,A10,'All cases'!$J:$J,"demanded") | F10: =COUNTIFS('All cases'!$A:$A,A10,'All cases'!$J:$J,"waived") | G10: =COUNTIFS('All cases'!$A:$A,A10,'All cases'!$K:$K,">0") | H10: =SUMIFS('All cases'!$K:$K,'All cases'!$A:$A,A10,'All cases'!$E:$E,"scheduled") | I10: =COUNTIFS('All cases'!$A:$A,A10,'All cases'!$Q:$Q,">0")
A11: Total | B11: =SUM(B5:B10) | C11: =SUM(C5:C10) | D11: =SUM(D5:D10) | E11: =SUM(E5:E10) | F11: =SUM(F5:F10) | G11: =SUM(G5:G10) | H11: =SUM(H5:H10) | I11: =SUM(I5:I10)

Sheet All cases
A1: County | B1: Sale date | C1: Sale # | D1: Case # | E1: Status | F1: Address | G1: TMS | H1: Plaintiff | I1: Defendant | J1: Deficiency | K1: Judgment $ | L1: As of | M1: Per diem $ | N1: Days to sale | O1: Est. owed sale day $ | P1: Interest | Q1: County FMV $ | R1: Debt ÷ FMV | S1: Acreage | T1: Land use / type | U1: Year built | V1: Sq ft | W1: Record owner | X1: Last sale | Y1: Order / judgment | Z1: Notice | AA1: Docket | AB1: Property card | AC1: Write-up
A2: Georgetown | B2: 46273 | D2: 2026-CP-22-00295 | E2: cancelled | F2: 1105 Merriman Rd., Georgetown, SC | G2: 05-0003-012-00-00 | H2: U. S. Bank Trust Comp. | I2: Brownstone Prop. | J2: demanded | N2: =IF(OR(B2="",L2=""),"",MAX(0,B2-L2)) | O2: =IF(K2="","",K2+IF(OR(M2="",N2=""),0,M2*N2)) | R2: =IF(OR(Q2="",Q2=0,O2=""),"",O2/Q2) | AC2: 1105 Merriman Rd., Georgetown, SC. Judgment $ not pulled yet (needs the PC run). DEFICIENCY DEMANDED — open 30 days. STATUS: CANCELLED.
A3: Georgetown | B3: 46273 | D3: 2025-CP-22-01076 | E3: scheduled | F3: 83 Polan Lane Georgetown, SC | G3: 03-0439-025-01-00 | H3: Howard and Howard | I3: Est. Bobbie Cuttino | J3: waived | N3: =IF(OR(B3="",L3=""),"",MAX(0,B3-L3)) | O3: =IF(K3="","",K3+IF(OR(M3="",N3=""),0,M3*N3)) | R3: =IF(OR(Q3="",Q3=0,O3=""),"",O3/Q3) | AC3: 83 Polan Lane Georgetown, SC. Judgment $ not pulled yet (needs the PC run). Deficiency waived — final on the day.
A4: Georgetown | B4: 46273 | D4: 2026-CP-22-00122 | E4: scheduled | F4: 1832 Middleton St., Georgetown, SC | G4: 02-0107-141-00-00 | H4: SouthState Bank | I4: Roland Floyd | J4: waived | N4: =IF(OR(B4="",L4=""),"",MAX(0,B4-L4)) | O4: =IF(K4="","",K4+IF(OR(M4="",N4=""),0,M4*N4)) | R4: =IF(OR(Q4="",Q4=0,O4=""),"",O4/Q4) | AC4: 1832 Middleton St., Georgetown, SC. Judgment $ not pulled yet (needs the PC run). Deficiency waived — final on the day.
A5: Georgetown | B5: 46273 | D5: 2025-CP-22-01043 | E5: cancelled | F5: 147 Rubin Av., Georgetown, SC | G5: 02-0203-039-00-00 | H5: Nationstar Mortgage | I5: David J. Smith | J5: waived | N5: =IF(OR(B5="",L5=""),"",MAX(0,B5-L5)) | O5: =IF(K5="","",K5+IF(OR(M5="",N5=""),0,M5*N5)) | R5: =IF(OR(Q5="",Q5=0,O5=""),"",O5/Q5) | AC5: 147 Rubin Av., Georgetown, SC. Judgment $ not pulled yet (needs the PC run). Deficiency waived — final on the day. STATUS: CANCELLED.
A6: Georgetown | B6: 46273 | D6: 2025-CP-22-00093 | E6: scheduled | F6: 73 Magill Lane, Georgetown, SC | G6: 01-0120-047-00-00 | H6: REV Federal Cred. Union | I6: Ralph Hoffman | J6: demanded | N6: =IF(OR(B6="",L6=""),"",MAX(0,B6-L6)) | O6: =IF(K6="","",K6+IF(OR(M6="",N6=""),0,M6*N6)) | R6: =IF(OR(Q6="",Q6=0,O6=""),"",O6/Q6) | AC6: 73 Magill Lane, Georgetown, SC. Judgment $ not pulled yet (needs the PC run). DEFICIENCY DEMANDED — open 30 days.
A7: Georgetown | B7: 46273 | D7: 2025-CP-22-00127 | E7: scheduled | F7: 5457 Huntington Marsh Rd., Murrells Inlet, SC | G7: 04-0101-005-00-00 | H7: Selene Finance | I7: John H. Oakes | J7: waived | N7: =IF(OR(B7="",L7=""),"",MAX(0,B7-L7)) | O7: =IF(K7="","",K7+IF(OR(M7="",N7=""),0,M7*N7)) | R7: =IF(OR(Q7="",Q7=0,O7=""),"",O7/Q7) | AC7: 5457 Huntington Marsh Rd., Murrells Inlet, SC. Judgment $ not pulled yet (needs the PC run). Deficiency waived — final on the day.
A8: Georgetown | B8: 46273 | D8: 2025-CP-22-00906 | E8: scheduled | F8: 23 Orchard Ave., Murrells Inlet, SC | G8: 41-0118-008-01-24 | H8: Citibank, N.A. | I8: Kim Brackett | J8: waived | N8: =IF(OR(B8="",L8=""),"",MAX(0,B8-L8)) | O8: =IF(K8="","",K8+IF(OR(M8="",N8=""),0,M8*N8)) | R8: =IF(OR(Q8="",Q8=0,O8=""),"",O8/Q8) | AC8: 23 Orchard Ave., Murrells Inlet, SC. Judgment $ not pulled yet (needs the PC run). Deficiency waived — final on the day.
A9: Greenville | B9: 46273 | C9: 1 | D9: 2016-CP-23-06737 | E9: withdrawn | F9: 128 Wild Dogwood Way Greenville, SC 29605 | H9: American Capital Group, LLC | I9: Louise A. Schiminger | J9: demanded | N9: =IF(OR(B9="",L9=""),"",MAX(0,B9-L9)) | O9: =IF(K9="","",K9+IF(OR(M9="",N9=""),0,M9*N9)) | R9: =IF(OR(Q9="",Q9=0,O9=""),"",O9/Q9) | Z9: open | AC9: 128 Wild Dogwood Way Greenville, SC 29605. Judgment $ not pulled yet (needs the PC run). DEFICIENCY DEMANDED — open 30 days. STATUS: WITHDRAWN.
A10: Greenville | B10: 46273 | C10: 2 | D10: 2024-CP-23-03628 | E10: scheduled | F10: 9-A Stadium Drive Greenville, SC 29609 | H10: HSBC Bank USA, N.A., as Trustee for ACE Securities Corp. Home Equity Loan Trust, Series 2007-HE2 | I10: Heirs-at-law or devisees of Edgar B. Walker, deceased, et al | J10: waived | K10: 94593 | N10: =IF(OR(B10="",L10=""),"",MAX(0,B10-L10)) | O10: =IF(K10="","",K10+IF(OR(M10="",N10=""),0,M10*N10)) | Q10: 218570 | R10: =IF(OR(Q10="",Q10=0,O10=""),"",O10/Q10) | S10: 0.520 | T10: 1100 (Single Family) | W10: Walker Lonietta Y | X10: 06/30/2006 $98,000 | Y10: open | Z10: open | AB10: open | AC10: 9-A Stadium Drive Greenville, SC 29609 — 1100 (Single Family) — 0.520 ac. Record owner Walker Lonietta Y. Last transfer 06/30/2006 for $98,000. County FMV $218,570.00. Judgment $94,593.00. Debt is 43% of FMV — real equity, expect third-party bidding. Deficiency waived — final on the day.
A11: Greenville | B11: 46273 | C11: 3 | D11: 2024-CP-23-07423 | E11: scheduled | F11: 304 Weddington Lane Simpsonville, SC 29681 | H11: New Silver Lending, LLC | I11: Key-Line Capital Investment Group, LLC | J11: demanded | K11: 331126 | N11: =IF(OR(B11="",L11=""),"",MAX(0,B11-L11)) | O11: =IF(K11="","",K11+IF(OR(M11="",N11=""),0,M11*N11)) | Q11: 95000 | R11: =IF(OR(Q11="",Q11=0,O11=""),"",O11/Q11) | S11: 0.150 | T11: 1180 (Residential Vacant) | W11: Key-Line Capital Investment Gr | X11: 01/23/2024 $5 | Y11: open | Z11: open | AB11: open | AC11: 304 Weddington Lane Simpsonville, SC 29681 — 1180 (Residential Vacant) — 0.150 ac (Linden Park). Record owner Key-Line Capital Investment Gr. Last transfer 01/23/2024 for $5. County FMV $95,000.00. Judgment $331,126.00. Debt exceeds FMV (349%) — plaintiff will likely take it back. DEFICIENCY DEMANDED — open 30 days.
A12: Greenville | B12: 46273 | C12: 4 | D12: 2025-CP-23-03722 | E12: scheduled | F12: 608 Rhett Street Greenville, SC 29601 | H12: Kiavi Funding, Inc. | I12: VSWC LLC | J12: demanded | K12: 482293 | N12: =IF(OR(B12="",L12=""),"",MAX(0,B12-L12)) | O12: =IF(K12="","",K12+IF(OR(M12="",N12=""),0,M12*N12)) | Q12: 392670 | R12: =IF(OR(Q12="",Q12=0,O12=""),"",O12/Q12) | S12: 0.100 | T12: 1100 (Single Family) | W12: Vswc Llc | X12: 11/13/2023 $400,000 | Y12: open | Z12: open | AB12: open | AC12: 608 Rhett Street Greenville, SC 29601 — 1100 (Single Family) — 0.100 ac. Record owner Vswc Llc. Last transfer 11/13/2023 for $400,000. County FMV $392,670.00. Judgment $482,293.00. Debt exceeds FMV (123%) — plaintiff will likely take it back. DEFICIENCY DEMANDED — open 30 days.
A13: Greenville | B13: 46273 | C13: 5 | D13: 2025-CP-23-05048 | E13: scheduled | F13: 4 Point Hope Court Greenville, SC 29605 | H13: South Carolina State Housing Finance and Development Authority | I13: Sharon Diane Culpepper-Booker | J13: waived | K13: 179057 | N13: =IF(OR(B13="",L13=""),"",MAX(0,B13-L13)) | O13: =IF(K13="","",K13+IF(OR(M13="",N13=""),0,M13*N13)) | Q13: 235180 | R13: =IF(OR(Q13="",Q13=0,O13=""),"",O13/Q13) | S13: 0 | T13: 1100 (Single Family) | W13: Culpepper-Booker Sharon Diane | X13: 09/29/2020 $179,000 | Y13: open | Z13: open | AB13: open | AC13: 4 Point Hope Court Greenville, SC 29605 — 1100 (Single Family) (Oak Knoll). Record owner Culpepper-Booker Sharon Diane. Last transfer 09/29/2020 for $179,000. County FMV $235,180.00. Judgment $179,057.00. Debt is 76% of FMV — thin margin. Deficiency waived — final on the day.
A14: Greenville | B14: 46273 | C14: 6 | D14: 2025-CP-23-06065 | E14: withdrawn | F14: 110 Water Reach Lane Simpsonville, SC 29681 | H14: SELENE FINANCE LP | I14: John Clement Shaugnessy | J14: waived | N14: =IF(OR(B14="",L14=""),"",MAX(0,B14-L14)) | O14: =IF(K14="","",K14+IF(OR(M14="",N14=""),0,M14*N14)) | R14: =IF(OR(Q14="",Q14=0,O14=""),"",O14/Q14) | Z14: open | AC14: 110 Water Reach Lane Simpsonville, SC 29681. Judgment $ not pulled yet (needs the PC run). Deficiency waived — final on the day. STATUS: WITHDRAWN.
A15: Greenville | B15: 46273 | C15: 7 | D15: 2025-CP-23-06198 | E15: withdrawn | F15: 603 Stallings Rd Taylors, SC 29687 | H15: Planet Home Lending, LLC | I15: Crystal Lynn Patterson | J15: waived | N15: =IF(OR(B15="",L15=""),"",MAX(0,B15-L15)) | O15: =IF(K15="","",K15+IF(OR(M15="",N15=""),0,M15*N15)) | R15: =IF(OR(Q15="",Q15=0,O15=""),"",O15/Q15) | Z15: open | AC15: 603 Stallings Rd Taylors, SC 29687. Judgment $ not pulled yet (needs the PC run). Deficiency waived — final on the day. STATUS: WITHDRAWN.
A16: Greenville | B16: 46273 | C16: 8 | D16: 2025-CP-23-06584 | E16: scheduled | F16: 39B W Golden Strip Drive Mauldin, SC 29662 | H16: South Carolina State Housing Finance and Development Authority | I16: Dominique Smith | J16: waived | K16: 68468.05 | N16: =IF(OR(B16="",L16=""),"",MAX(0,B16-L16)) | O16: =IF(K16="","",K16+IF(OR(M16="",N16=""),0,M16*N16)) | Q16: 244440 | R16: =IF(OR(Q16="",Q16=0,O16=""),"",O16/Q16) | S16: 0.340 | T16: 1100 (Single Family) | W16: Ladson Alice D | X16: 05/20/2014 $132,500 | Y16: open | Z16: open | AB16: open | AC16: 39B W Golden Strip Drive Mauldin, SC 29662 — 1100 (Single Family) — 0.340 ac. Record owner Ladson Alice D (card is for 39 W GOLDEN STRIP DR — unit letter not on file, verify). Last transfer 05/20/2014 for $132,500. County FMV $244,440.00. Judgment $68,468.05. Debt is 28% of FMV — real equity, expect third-party bidding. Deficiency waived — final on the day.
A17: Greenville | B17: 46273 | C17: 9 | D17: 2025-CP-23-06604 | E17: scheduled | F17: 15 Fennec Drive Fountain Inn, SC 29644 | H17: South Carolina State Housing Finance and Development Authority | I17: Brandon Andre Roane | J17: demanded | K17: 279737 | N17: =IF(OR(B17="",L17=""),"",MAX(0,B17-L17)) | O17: =IF(K17="","",K17+IF(OR(M17="",N17=""),0,M17*N17)) | Q17: 289220 | R17: =IF(OR(Q17="",Q17=0,O17=""),"",O17/Q17) | S17: 0 | T17: 1100 (Single Family) | W17: Roane Brandon Andre | X17: 05/11/2023 $262,999 | Y17: open | Z17: open | AB17: open | AC17: 15 Fennec Drive Fountain Inn, SC 29644 — 1100 (Single Family) (Fox Tail Cottages). Record owner Roane Brandon Andre. Last transfer 05/11/2023 for $262,999. County FMV $289,220.00. Judgment $279,737.00. Debt is 97% of FMV — thin margin. DEFICIENCY DEMANDED — open 30 days.
A18: Greenville | B18: 46273 | C18: 10 | D18: 2025-CP-23-06612 | E18: scheduled | F18: 104 Pine Needle Road Piedmont, SC 29673 | H18: South Carolina State Housing Finance and Development Authority | I18: Ashley Rhodes | J18: waived | K18: 254440 | N18: =IF(OR(B18="",L18=""),"",MAX(0,B18-L18)) | O18: =IF(K18="","",K18+IF(OR(M18="",N18=""),0,M18*N18)) | Q18: 212830 | R18: =IF(OR(Q18="",Q18=0,O18=""),"",O18/Q18) | S18: 0 | T18: 1100 (Single Family) | W18: Rhodes Ashley | X18: 01/17/2024 $222,500 | Y18: open | Z18: open | AB18: open | AC18: 104 Pine Needle Road Piedmont, SC 29673 — 1100 (Single Family) (Pine Shadows). Record owner Rhodes Ashley. Last transfer 01/17/2024 for $222,500. County FMV $212,830.00. Judgment $254,440.00. Debt exceeds FMV (120%) — plaintiff will likely take it back. Deficiency waived — final on the day.
A19: Greenville | B19: 46273 | C19: 11 | D19: 2025-CP-23-07189 | E19: scheduled | F19: 402 Sienna Drive Greenville, SC 29609 | H19: U.S. Bank Trust National Association, as trustee for Legacy Mortgage Asset Trust 2021-GS4 | I19: Terry Tolbert | J19: waived | K19: 906485 | N19: =IF(OR(B19="",L19=""),"",MAX(0,B19-L19)) | O19: =IF(K19="","",K19+IF(OR(M19="",N19=""),0,M19*N19)) | R19: =IF(OR(Q19="",Q19=0,O19=""),"",O19/Q19) | Y19: open | Z19: open | AC19: 402 Sienna Drive Greenville, SC 29609. Judgment $906,485.00. Deficiency waived — final on the day.
A20: Greenville | B20: 46273 | C20: 12 | D20: 2025-CP-23-07612 | E20: scheduled | F20: 3 Black Oak Court Simpsonville, SC 29680 | H20: South Carolina State Housing Finance and Development Authority | I20: Maria Harley | J20: waived | K20: 269097 | N20: =IF(OR(B20="",L20=""),"",MAX(0,B20-L20)) | O20: =IF(K20="","",K20+IF(OR(M20="",N20=""),0,M20*N20)) | Q20: 278430 | R20: =IF(OR(Q20="",Q20=0,O20=""),"",O20/Q20) | S20: 0 | T20: 1100 (Single Family) | W20: Harley Maria | X20: 11/15/2023 $244,900 | Y20: open | Z20: open | AB20: open | AC20: 3 Black Oak Court Simpsonville, SC 29680 — 1100 (Single Family) (Standing Springs Estate). Record owner Harley Maria. Last transfer 11/15/2023 for $244,900. County FMV $278,430.00. Judgment $269,097.00. Debt is 97% of FMV — thin margin. Deficiency waived — final on the day.
A21: Greenville | B21: 46273 | C21: 13 | D21: 2025-CP-23-07667 | E21: withdrawn | F21: 406 Sandusky Lane Simpsonville, SC 29680 | H21: River Shoals Homeowners Association Inc | I21: Nancy Abad | J21: waived | N21: =IF(OR(B21="",L21=""),"",MAX(0,B21-L21)) | O21: =IF(K21="","",K21+IF(OR(M21="",N21=""),0,M21*N21)) | R21: =IF(OR(Q21="",Q21=0,O21=""),"",O21/Q21) | Z21: open | AC21: 406 Sandusky Lane Simpsonville, SC 29680. Judgment $ not pulled yet (needs the PC run). Deficiency waived — final on the day. STATUS: WITHDRAWN.
A22: Greenville | B22: 46273 | C22: 14 | D22: 2025-CP-23-08344 | E22: withdrawn | F22: 1904 Lake Cunningham Road Greer, SC 29651 | H22: New American Funding LLC f/k/a Broker Solutions, Inc. | I22: Michael Greene | J22: waived | N22: =IF(OR(B22="",L22=""),"",MAX(0,B22-L22)) | O22: =IF(K22="","",K22+IF(OR(M22="",N22=""),0,M22*N22)) | Q22: 410930 | R22: =IF(OR(Q22="",Q22=0,O22=""),"",O22/Q22) | S22: 0 | T22: 1170 (MH w/ land) | W22: Morales-Greene Emilia | X22: 06/27/2025 | Z22: open | AB22: open | AC22: 1904 Lake Cunningham Road Greer, SC 29651 — 1170 (MH w/ land) (Cunningham Downs). Record owner Morales-Greene Emilia. Last transfer 06/27/2025. County FMV $410,930.00. Judgment $ not pulled yet (needs the PC run). Deficiency waived — final on the day. STATUS: WITHDRAWN.
A23: Greenville | B23: 46273 | C23: 15 | D23: 2025-CP-23-08409 | E23: withdrawn | F23: 116 Ridgewater Court Fountain Inn, SC 29644 | H23: US Bank Trust National Association, as owner trustee for VRMTG Asset Trust | I23: Kathleen DeFrancesco | J23: waived | N23: =IF(OR(B23="",L23=""),"",MAX(0,B23-L23)) | O23: =IF(K23="","",K23+IF(OR(M23="",N23=""),0,M23*N23)) | R23: =IF(OR(Q23="",Q23=0,O23=""),"",O23/Q23) | Z23: open | AC23: 116 Ridgewater Court Fountain Inn, SC 29644. Judgment $ not pulled yet (needs the PC run). Deficiency waived — final on the day. STATUS: WITHDRAWN.
A24: Greenville | B24: 46273 | C24: 16 | D24: 2026-CP-23-00155 | E24: scheduled | F24: 1406 Winding Way Taylors, SC 29687 | H24: Rocket Mortgage, LLC f/k/a Quicken Loans, LLC | I24: Philip W. Dixon | J24: demanded | K24: 107886 | N24: =IF(OR(B24="",L24=""),"",MAX(0,B24-L24)) | O24: =IF(K24="","",K24+IF(OR(M24="",N24=""),0,M24*N24)) | Q24: 254770 | R24: =IF(OR(Q24="",Q24=0,O24=""),"",O24/Q24) | S24: 0 | T24: 1100 (Single Family) | W24: Dixon Sue Ann | X24: 12/01/2009 $10 | Y24: open | Z24: open | AB24: open | AC24: 1406 Winding Way Taylors, SC 29687 — 1100 (Single Family) (Peppertree). Record owner Dixon Sue Ann. Last transfer 12/01/2009 for $10. County FMV $254,770.00. Judgment $107,886.00. Debt is 42% of FMV — real equity, expect third-party bidding. DEFICIENCY DEMANDED — open 30 days.
A25: Greenville | B25: 46273 | C25: 17 | D25: 2026-CP-23-00195 | E25: withdrawn | F25: 19 and 21 Whiller Drive Greenville, SC 29608 | H25: Moneyline Ventures, LLC | I25: A.S.K. Enterprises & Funding, LLC | J25: waived | N25: =IF(OR(B25="",L25=""),"",MAX(0,B25-L25)) | O25: =IF(K25="","",K25+IF(OR(M25="",N25=""),0,M25*N25)) | R25: =IF(OR(Q25="",Q25=0,O25=""),"",O25/Q25) | Z25: open | AC25: 19 and 21 Whiller Drive Greenville, SC 29608. Judgment $ not pulled yet (needs the PC run). Deficiency waived — final on the day. STATUS: WITHDRAWN.
A26: Greenville | B26: 46273 | C26: 18 | D26: 2026-CP-23-00512 | E26: scheduled | F26: 104 Oak Forest Drive Greer, SC 29650 | H26: Carrington Mortgage Services, LLC | I26: Chad Thompson | J26: waived | K26: 408231 | N26: =IF(OR(B26="",L26=""),"",MAX(0,B26-L26)) | O26: =IF(K26="","",K26+IF(OR(M26="",N26=""),0,M26*N26)) | Q26: 522800 | R26: =IF(OR(Q26="",Q26=0,O26=""),"",O26/Q26) | S26: 0 | T26: 1100 (Single Family) | W26: Thompson Chad | X26: 04/11/2022 $389,900 | Y26: open | Z26: open | AB26: open | AC26: 104 Oak Forest Drive Greer, SC 29650 — 1100 (Single Family). Record owner Thompson Chad. Last transfer 04/11/2022 for $389,900. County FMV $522,800.00. Judgment $408,231.00. Debt is 78% of FMV — thin margin. Deficiency waived — final on the day.
A27: Greenville | B27: 46273 | C27: 19 | D27: 2026-CP-23-00555 | E27: withdrawn | F27: 67 Wallace Street Greenville, SC 29605 | H27: Greenville County Redevelopment Authority | I27: Sylvia G. Hammett | J27: waived | N27: =IF(OR(B27="",L27=""),"",MAX(0,B27-L27)) | O27: =IF(K27="","",K27+IF(OR(M27="",N27=""),0,M27*N27)) | R27: =IF(OR(Q27="",Q27=0,O27=""),"",O27/Q27) | Z27: open | AC27: 67 Wallace Street Greenville, SC 29605. Judgment $ not pulled yet (needs the PC run). Deficiency waived — final on the day. STATUS: WITHDRAWN.
A28: Greenville | B28: 46273 | C28: 20 | D28: 2026-CP-23-00730 | E28: scheduled | F28: 100 N. Markley St. Greenville, SC 29601 | H28: The Fidelity Bank | I28: Greenville HKW, LLC | J28: waived | K28: 4572030.1 | N28: =IF(OR(B28="",L28=""),"",MAX(0,B28-L28)) | O28: =IF(K28="","",K28+IF(OR(M28="",N28=""),0,M28*N28)) | Q28: 2973000 | R28: =IF(OR(Q28="",Q28=0,O28=""),"",O28/Q28) | S28: 0.910 | T28: 6800 (Commercial Vacant ) | W28: Greenville Hkw Llc | X28: 12/16/2019 | Y28: open | Z28: open | AB28: open | AC28: 100 N. Markley St. Greenville, SC 29601 — 6800 (Commercial Vacant ) — 0.910 ac. Record owner Greenville Hkw Llc. Last transfer 12/16/2019. County FMV $2,973,000.00. Judgment $4,572,030.10. Debt exceeds FMV (154%) — plaintiff will likely take it back. Deficiency waived — final on the day.
A29: Greenville | B29: 46273 | C29: 21 | D29: 2026-CP-23-01255 | E29: withdrawn | F29: 23 Chinaberry Lane Simpsonville, SC 29680 | H29: Truist Bank | I29: Doris B. Pressley | J29: waived | N29: =IF(OR(B29="",L29=""),"",MAX(0,B29-L29)) | O29: =IF(K29="","",K29+IF(OR(M29="",N29=""),0,M29*N29)) | R29: =IF(OR(Q29="",Q29=0,O29=""),"",O29/Q29) | Z29: open | AC29: 23 Chinaberry Lane Simpsonville, SC 29680. Judgment $ not pulled yet (needs the PC run). Deficiency waived — final on the day. STATUS: WITHDRAWN.
A30: Greenville | B30: 46273 | C30: 22 | D30: 2026-CP-23-01348 | E30: withdrawn | F30: 302 West Road Travelers Rest, SC 29690 | H30: Rocket Mortgage, LLC f/k/a Quicken Loans, LLC | I30: Wanda Brown | J30: waived | N30: =IF(OR(B30="",L30=""),"",MAX(0,B30-L30)) | O30: =IF(K30="","",K30+IF(OR(M30="",N30=""),0,M30*N30)) | R30: =IF(OR(Q30="",Q30=0,O30=""),"",O30/Q30) | Z30: open | AC30: 302 West Road Travelers Rest, SC 29690. Judgment $ not pulled yet (needs the PC run). Deficiency waived — final on the day. STATUS: WITHDRAWN.
A31: Greenville | B31: 46273 | C31: 23 | D31: 2026-CP-23-01483 | E31: scheduled | F31: 304 Glenlea Ln Greenville, SC 29617 | H31: Finance of America Reverse LLC | I31: Robert Luther Ellis, Jr as Personal Representative for the Estate of Beverly Staton | J31: waived | K31: 153841.1 | N31: =IF(OR(B31="",L31=""),"",MAX(0,B31-L31)) | O31: =IF(K31="","",K31+IF(OR(M31="",N31=""),0,M31*N31)) | Q31: 224920 | R31: =IF(OR(Q31="",Q31=0,O31=""),"",O31/Q31) | S31: 0.120 | T31: 1100 (Single Family) | W31: Staton Beverly | X31: 11/15/2004 $105,000 | Y31: open | Z31: open | AB31: open | AC31: 304 Glenlea Ln Greenville, SC 29617 — 1100 (Single Family) — 0.120 ac (The Village At Glenlea). Record owner Staton Beverly. Last transfer 11/15/2004 for $105,000. County FMV $224,920.00. Judgment $153,841.10. Debt is 68% of FMV — real equity, expect third-party bidding. Deficiency waived — final on the day.
A32: Greenville | B32: 46273 | C32: 24 | D32: 2026-CP-23-02327 | E32: scheduled | F32: 71 Dorsey Avenue Greenville, SC 29611 | H32: Wilmington Savings Fund Society, FSB, as Owner Trustee for the FLIC Residential Mortgage Loan Trust 1 | I32: VSWC LLC | J32: waived | K32: 246879.23 | N32: =IF(OR(B32="",L32=""),"",MAX(0,B32-L32)) | O32: =IF(K32="","",K32+IF(OR(M32="",N32=""),0,M32*N32)) | Q32: 246770 | R32: =IF(OR(Q32="",Q32=0,O32=""),"",O32/Q32) | S32: 0.210 | T32: 1100 (Single Family) | W32: Vswc Llc | X32: 10/05/2021 $100,000 | Y32: open | Z32: open | AB32: open | AC32: 71 Dorsey Avenue Greenville, SC 29611 — 1100 (Single Family) — 0.210 ac (Abney Mills). Record owner Vswc Llc. Last transfer 10/05/2021 for $100,000. County FMV $246,770.00. Judgment $246,879.23. Debt exceeds FMV (100%) — plaintiff will likely take it back. Deficiency waived — final on the day.
A33: Greenville | B33: 46273 | C33: 25 | D33: 2026-CP-23-02343 | E33: scheduled | F33: 37 Ross Street Greenville, SC 29611 | H33: Wilmington Savings Fund Society, FSB, as Trustee of NMLT 2021-INV1 Trust | I33: VSWC LLC | J33: waived | K33: 159379.2 | N33: =IF(OR(B33="",L33=""),"",MAX(0,B33-L33)) | O33: =IF(K33="","",K33+IF(OR(M33="",N33=""),0,M33*N33)) | Q33: 183180 | R33: =IF(OR(Q33="",Q33=0,O33=""),"",O33/Q33) | S33: 0 | T33: 1100 (Single Family) | W33: Vswc Llc | X33: 05/21/2020 $10 | Y33: open | Z33: open | AB33: open | AC33: 37 Ross Street Greenville, SC 29611 — 1100 (Single Family). Record owner Vswc Llc. Last transfer 05/21/2020 for $10. County FMV $183,180.00. Judgment $159,379.20. Debt is 87% of FMV — thin margin. Deficiency waived — final on the day.
A34: Greenville | B34: 46273 | C34: 26 | D34: 2026-CP-23-02408 | E34: scheduled | F34: 11 Charing Cross Road Taylors, SC 29687 | H34: Wilmington Savings Fund Society, FSB, as trustee for Ibis Holdings A Trust | I34: GRM Properties | J34: demanded | K34: 219174.3 | N34: =IF(OR(B34="",L34=""),"",MAX(0,B34-L34)) | O34: =IF(K34="","",K34+IF(OR(M34="",N34=""),0,M34*N34)) | Q34: 267670 | R34: =IF(OR(Q34="",Q34=0,O34=""),"",O34/Q34) | S34: 0 | T34: 1100 (Single Family) | W34: Grm Properties Of South Caroli | X34: 08/12/2022 $235,000 | Y34: open | Z34: open | AB34: open | AC34: 11 Charing Cross Road Taylors, SC 29687 — 1100 (Single Family) (Brookwood Forest). Record owner Grm Properties Of South Caroli. Last transfer 08/12/2022 for $235,000. County FMV $267,670.00. Judgment $219,174.30. Debt is 82% of FMV — thin margin. DEFICIENCY DEMANDED — open 30 days.
A35: Greenville | B35: 46273 | C35: 27 | D35: 2026-CP-23-02884 | E35: scheduled | F35: 2501 Poinsett Highway Greenville, SC 29609 | H35: ALFIE Investors LLC | I35: 2501 Poinsette LLC | J35: demanded | K35: 301030.64 | N35: =IF(OR(B35="",L35=""),"",MAX(0,B35-L35)) | O35: =IF(K35="","",K35+IF(OR(M35="",N35=""),0,M35*N35)) | Q35: 306870 | R35: =IF(OR(Q35="",Q35=0,O35=""),"",O35/Q35) | S35: 0 | T35: 1100 (Single Family) | W35: 2501 Poinsette Llc | X35: 05/02/2022 $130,000 | Y35: open | Z35: open | AB35: open | AC35: 2501 Poinsett Highway Greenville, SC 29609 — 1100 (Single Family). Record owner 2501 Poinsette Llc. Last transfer 05/02/2022 for $130,000. County FMV $306,870.00. Judgment $301,030.64. Debt is 98% of FMV — thin margin. DEFICIENCY DEMANDED — open 30 days.
A36: Greenville | B36: 46273 | C36: 28 | D36: 2026-CP-23-03000 | E36: scheduled | F36: 202 Port Road Greenville, SC 29617 | H36: UMB Bank, National Association, as owner trustee for Verus Securitization Trust 2024-6 | I36: Green Ant LLC | J36: waived | K36: 221056.42 | N36: =IF(OR(B36="",L36=""),"",MAX(0,B36-L36)) | O36: =IF(K36="","",K36+IF(OR(M36="",N36=""),0,M36*N36)) | Q36: 249890 | R36: =IF(OR(Q36="",Q36=0,O36=""),"",O36/Q36) | S36: 0.590 | T36: 1100 (Single Family) | W36: Green Ant Llc | X36: 05/16/2023 $249,900 | Y36: open | Z36: open | AB36: open | AC36: 202 Port Road Greenville, SC 29617 — 1100 (Single Family) — 0.590 ac (River Valley). Record owner Green Ant Llc. Last transfer 05/16/2023 for $249,900. County FMV $249,890.00. Judgment $221,056.42. Debt is 88% of FMV — thin margin. Deficiency waived — final on the day.
A37: Greenville | B37: 46273 | C37: 29 | D37: 2026-CP-23-03232 | E37: withdrawn | F37: 608 Kingsmoor Drive Simpsonville, SC 29681 | H37: Mortgage Solutions of Colorado, LLC d/b/a Mortgage Solutions Financial | I37: Josh Massengill | J37: waived | N37: =IF(OR(B37="",L37=""),"",MAX(0,B37-L37)) | O37: =IF(K37="","",K37+IF(OR(M37="",N37=""),0,M37*N37)) | R37: =IF(OR(Q37="",Q37=0,O37=""),"",O37/Q37) | Z37: open | AC37: 608 Kingsmoor Drive Simpsonville, SC 29681. Judgment $ not pulled yet (needs the PC run). Deficiency waived — final on the day. STATUS: WITHDRAWN.
A38: Horry | B38: 46273 | D38: 2026-CP-26-02004 | E38: scheduled | F38: 1207 S Ocean Blvd, Unit 50801, Myrtle Beach, SC 29577 | G38: 1811302158 | J38: demanded | K38: 77686.29 | N38: =IF(OR(B38="",L38=""),"",MAX(0,B38-L38)) | O38: =IF(K38="","",K38+IF(OR(M38="",N38=""),0,M38*N38)) | R38: =IF(OR(Q38="",Q38=0,O38=""),"",O38/Q38) | Y38: open | AC38: 1207 S Ocean Blvd, Unit 50801, Myrtle Beach, SC 29577. Judgment $77,686.29. DEFICIENCY DEMANDED — open 30 days.
A39: Horry | B39: 46273 | D39: 2026-CP-26-02004 | E39: scheduled | F39: 1207 S Ocean Blvd, Unit 50901, Myrtle Beach, SC 29577 | G39: 1811302171 | J39: demanded | K39: 77686.29 | N39: =IF(OR(B39="",L39=""),"",MAX(0,B39-L39)) | O39: =IF(K39="","",K39+IF(OR(M39="",N39=""),0,M39*N39)) | R39: =IF(OR(Q39="",Q39=0,O39=""),"",O39/Q39) | Y39: open | AC39: 1207 S Ocean Blvd, Unit 50901, Myrtle Beach, SC 29577. Judgment $77,686.29. DEFICIENCY DEMANDED — open 30 days.
A40: Horry | B40: 46273 | D40: 2026-CP-26-02004 | E40: scheduled | F40: 1207 S Ocean Blvd, Unit 50902, Myrtle Beach, SC 29577 | G40: 1811302172 | J40: demanded | K40: 77686.29 | N40: =IF(OR(B40="",L40=""),"",MAX(0,B40-L40)) | O40: =IF(K40="","",K40+IF(OR(M40="",N40=""),0,M40*N40)) | R40: =IF(OR(Q40="",Q40=0,O40=""),"",O40/Q40) | Y40: open | AC40: 1207 S Ocean Blvd, Unit 50902, Myrtle Beach, SC 29577. Judgment $77,686.29. DEFICIENCY DEMANDED — open 30 days.
...

Sheet Sale calendar
A1: County | B1: Sale day rule | C1: Time | D1: Location | E1: Next dates | F1: Notes
A2: Greenville | B2: 1st Monday (Tue if holiday) | C2: 11:00 AM | D2: Greenville County Courthouse, 305 E North St, judicial wing | E2: Sep 8 · Oct 5 · Nov 2 · Dec 7 2026 | F2: 5% deposit; deficiency re-bid day 30 (Oct 8 for the Sept sale)
A3: Pickens | B3: 1st Monday (Tue if holiday) | C3: 11:00 AM | D3: Pickens County Courthouse, 2nd floor, Courtroom #1 | E3: Sep 8 · Oct 5 · Nov 2 · Dec 7 2026 | F3: Deficiency re-bid Oct 8 2026 11:00 AM, Courtroom #4 or #2
A4: Spartanburg | B4: 1st Monday (Tue if holiday) | C4: 11:00 AM | D4: 180 Magnolia St, 4th floor, Courtroom 4-A | E4: Sep 8 · Oct 5 · Nov 2 · Dec 7 2026 | F4: Deficiency sales ~30 days later (county posts a Deficiency Sale doc)
A5: Oconee | B5: 1st Monday (Tue if holiday) | C5: 11:00 AM | D5: Oconee County Courthouse, Walhalla | E5: Sep 8 · Oct 5 · Nov 2 · Dec 7 2026 | F5: List on the SC Public Index roster (Master In Equity)
A6: Horry | B6: 1st Monday (Tue if holiday) | C6: 11:00 AM | D6: 1301 2nd Ave, 3rd floor, Conway | E6: Sep 8 · Oct 5 · Nov 2 · Dec 7 2026 | F6: New bidders register 7 days ahead; first-time winners bring $2,500 certified
A7: Charleston | B7: 1st TUESDAY | C7: 11:00 AM | D7: County Council Chambers, PSB, 4045 Bridge View Dr, N. Charleston | E7: Oct 6 · Nov 3 · Dec 1 2026 | F7: REGISTER by noon the Monday before (form + photo ID); re-open sales Thursdays at 100 Broad St, Courtroom 2A
A8: Georgetown | B8: 1st Monday | C8: 12:00 NOON | D8: 401 Cleland St, 2nd floor MIE courtroom | E8: Sep 8 (confirm) · Oct 5 · Nov 2 · Dec 7 2026 | F8: Holiday rule is "next day or next Monday" – confirm September (843-546-3103)
A9: Beaufort | B9: 1st Monday (next business day if holiday) | C9: 11:00 AM | D9: 102 Ribaut Rd, 2nd floor, Beaufort | E9: Sep 8 · Oct 5 · Nov 2 · Dec 7 2026 | F9: List: notebook outside MIE office + Public Index roster
A10: Berkeley | B10: 1st WEDNESDAY | C10: 11:00 AM | D10: Courtroom B, 300-B California Ave, Moncks Corner | E10: Oct 7 · Nov 4 · Dec 2 2026 | F10: MIE (843) 719-4432
A11: Dorchester | B11: UNVERIFIED – assumed 1st Monday | C11: 11:00 AM (assumed) | D11: St. George courthouse | E11: Oct 5 · Nov 2 · Dec 7 2026 (confirm) | F11: Confirm with Clerk (843) 563-0120
A12: Colleton | B12: UNVERIFIED – assumed 1st Monday | C12: 11:00 AM (assumed) | D12: Walterboro courthouse | E12: Oct 5 · Nov 2 · Dec 7 2026 (confirm) | F12: Confirm with Clerk (843) 549-5791

Sheet Read me
A1: How to read this workbook
A2: Judgment $ = the total the court entered (Order of Foreclosure / Form 4). Horry and Charleston publish it on their sale lists; other counties need the court-index run from Brian's PC (tools/foreclosures in the hello-world repo).
A3: Est. owed sale day = Judgment $ + per diem × days between the as-of date and the sale. This is the plaintiff's credit-bid ceiling, not the opening bid.
A4: Deficiency demanded = bidding stays open 30 days; anyone can top the day-of bid at the re-open. Waived = sale is final that day. "conflicting" = the notice says both; call plaintiff's counsel.
A5: Debt ÷ FMV under ~70% = real equity, expect competition; over 100% = plaintiff likely takes it back.
A6: County FMV / owner / acreage come from the county property card (Greenville live; qPublic counties need the PC run).
A7: Source of each row: Greenville = MIE sale list PDF (transcribed); Pickens = county roster PDF; Spartanburg = Spartan Weekly notices; Horry = county Principal Sales page; Georgetown = county DocumentCenter list; Charleston = Master's running list.
A8: Generated 2026-09-08 by tools/foreclosures/scripts/build-xlsx.py.
